{
    "checksum": "e58555d0a7b002f31f8d0749f085f49b66301558f435ff4501e837c899977bd3",
    "file": "31.md",
    "mime": {
        "encoding": "us-ascii",
        "type": "text/plain"
    },
    "number_of_duplicates": 2,
    "package": "python-vulndb",
    "path": "python-vulndb/0.1.3-2/vulndb/db/en/fix/31.md",
    "pkg_infos": {
        "area": "main",
        "copyright": true,
        "ctags_count": 0,
        "license": "/copyright/license/python-vulndb/0.1.3-2/",
        "metric": {
            "size": 1020
        },
        "pts_link": "https://tracker.debian.org/pkg/python-vulndb",
        "sloc": [
            [
                "python",
                447
            ],
            [
                "sh",
                196
            ],
            [
                "makefile",
                2
            ]
        ],
        "suites": [
            "bookworm",
            "bullseye",
            "sid"
        ],
        "vcs_browser": "https://salsa.debian.org/pkg-security-team/python-vulndb",
        "vcs_type": "git"
    },
    "raw_url": "/data/main/p/python-vulndb/0.1.3-2/vulndb/db/en/fix/31.md",
    "stat": {
        "perms": "rw-r--r--",
        "size": 144,
        "symlink_dest": null,
        "type": "-"
    },
    "text_file": true,
    "type": "file",
    "version": "0.1.3-2"
}