{
    "checksum": "89bee9bf0be387b2b5bc657b93d1a76201c64e25476bd1b1b52a3c05ff6a9bd5",
    "file": "0005-Fixed-bytes-unit-tests-fail-on-Python-3.5.patch",
    "mime": {
        "encoding": "us-ascii",
        "type": "text/x-diff"
    },
    "number_of_duplicates": 2,
    "package": "python-future",
    "path": "python-future/0.18.2-5/debian/patches/0005-Fixed-bytes-unit-tests-fail-on-Python-3.5.patch",
    "pkg_infos": {
        "area": "main",
        "copyright": true,
        "ctags_count": 0,
        "license": "/copyright/license/python-future/0.18.2-5/",
        "metric": {
            "size": 4264
        },
        "pts_link": "https://tracker.debian.org/pkg/python-future",
        "sloc": [
            [
                "python",
                43246
            ],
            [
                "makefile",
                136
            ],
            [
                "sh",
                29
            ]
        ],
        "suites": [
            "bookworm",
            "bullseye",
            "sid"
        ],
        "vcs_browser": "https://salsa.debian.org/python-team/packages/python-future",
        "vcs_type": "git"
    },
    "raw_url": "/data/main/p/python-future/0.18.2-5/debian/patches/0005-Fixed-bytes-unit-tests-fail-on-Python-3.5.patch",
    "stat": {
        "perms": "rw-r--r--",
        "size": 690,
        "symlink_dest": null,
        "type": "-"
    },
    "text_file": true,
    "type": "file",
    "version": "0.18.2-5"
}