{
    "checksum": "563e6f4c262fc411b269d1f44cc03af4af49b86130ffb300667813fb1744960c",
    "file": "known_failures.py",
    "mime": {
        "encoding": "us-ascii",
        "type": "text/x-python"
    },
    "number_of_duplicates": 2,
    "package": "python-gevent",
    "path": "python-gevent/21.8.0-1/src/gevent/tests/known_failures.py",
    "pkg_infos": {
        "area": "main",
        "copyright": true,
        "ctags_count": 0,
        "license": "/copyright/license/python-gevent/21.8.0-1/",
        "metric": {
            "size": 21664
        },
        "pts_link": "https://tracker.debian.org/pkg/python-gevent",
        "sloc": [
            [
                "python",
                165706
            ],
            [
                "ansic",
                74107
            ],
            [
                "sh",
                5488
            ],
            [
                "makefile",
                1543
            ],
            [
                "javascript",
                108
            ],
            [
                "awk",
                18
            ]
        ],
        "suites": [
            "bookworm",
            "sid"
        ],
        "vcs_browser": "https://salsa.debian.org/python-team/packages/python-gevent",
        "vcs_type": "git"
    },
    "raw_url": "/data/main/p/python-gevent/21.8.0-1/src/gevent/tests/known_failures.py",
    "stat": {
        "perms": "rw-r--r--",
        "size": 16051,
        "symlink_dest": null,
        "type": "-"
    },
    "text_file": true,
    "type": "file",
    "version": "21.8.0-1"
}