{
    "checksum": "72977911f53df8a5d80095ac77935d224b50c714f0e14c71fd270928d6c95e59",
    "file": "test_replace.py",
    "mime": {
        "encoding": "us-ascii",
        "type": "text/x-python"
    },
    "number_of_duplicates": 3,
    "package": "python-testfixtures",
    "path": "python-testfixtures/6.18.3-2/.pc/0004-tests-fix-with-Python-3.10-changed-exception-message.patch/testfixtures/tests/test_replace.py",
    "pkg_infos": {
        "area": "main",
        "copyright": true,
        "ctags_count": 0,
        "license": "/copyright/license/python-testfixtures/6.18.3-2/",
        "metric": {
            "size": 984
        },
        "pts_link": "https://tracker.debian.org/pkg/python-testfixtures",
        "sloc": [
            [
                "python",
                8810
            ],
            [
                "makefile",
                74
            ],
            [
                "sh",
                9
            ]
        ],
        "suites": [
            "bookworm",
            "sid"
        ],
        "vcs_browser": "https://salsa.debian.org/python-team/packages/python-testfixtures",
        "vcs_type": "git"
    },
    "raw_url": "/data/main/p/python-testfixtures/6.18.3-2/.pc/0004-tests-fix-with-Python-3.10-changed-exception-message.patch/testfixtures/tests/test_replace.py",
    "stat": {
        "perms": "rw-r--r--",
        "size": 13748,
        "symlink_dest": null,
        "type": "-"
    },
    "text_file": true,
    "type": "file",
    "version": "6.18.3-2"
}